Workbook
Name L_YN: '选项'!$A$1:$A$2
Name L_DIR: '选项'!$B$1:$B$3
Name L_OP: '选项'!$C$1:$C$3
Name L_CONF: '选项'!$D$1:$D$4
Name L_BASIS: '选项'!$E$1:$E$33

Sheet 说明
B2: 业务语义数据登记表（初稿·树形）
B3: 由《全省农商行2026年7月主要经营指标一览表》和《61家归因分析_202606》自动整理，需业务方确认。生成日期 2026-10-09。
B5: 怎么看这棵树
B6: 板块 | C6: 深蓝色整行，如“二、存款”。每个板块下是该板块的指标。
B7: 指标 | C7: 缩进越深，层级越低；点左侧“+/-”可以展开、收起下级。
B8: 〔拆解方式〕 | C8: 指标下面的分组，如〔按担保方式〕。同一个指标可以有多种拆法，每种拆法单独一组；“自动校验”列显示该组下级加起来是否等于上级。
B9: 比率 | C9: 灰色，挂在它的分子指标下面，如“个人存款占比”挂在“个人存款”下。
B10: ↪ 引用 | C10: 灰色斜体。该指标同时属于多个上级，完整的下级只在一处展开，其他地方以引用出现，备注里写了展开位置。
B12: 请业务方做的三件事
B13: ① 定默认口径 | C13: 在下方黄色单元格中选择：用户没说口径时默认用哪个（全局只定一次）。
B14: ② 核对树的结构 | C14: 上下级、拆解方式、加/减/其中是否正确；“自动校验”出现 ✗ 的组请在备注中说明原因。需要新增节点时插入一行，并填写最右侧的“上级指标”“拆解方式”。
B15: ③ 核对目录对应 | C15: 每个指标在“业务确认”列下拉选择：正确 / 有误（备注写正确指标）/ 目录中没有 / 不需要。顺带确认黄色建议列。
B17: 全局设置
B18: 默认口径（必填）
B20: 整理情况（自动统计）
B21: 指标数 | C21: =COUNTIF('指标树'!B3:B337,"指标")+COUNTIF('指标树'!B3:B337,"比率")
B22: 拆解分组数 | C22: =COUNTIF('指标树'!B3:B337,"拆解方式")
B23: 校验一致的分组 | C23: =COUNTIF('指标树'!F3:F337,"✓*")
B24: 校验不一致的分组 | C24: =COUNTIF('指标树'!F3:F337,"✗*")
B25: 目录中完全一致的指标 | C25: =COUNTIF('指标树'!K3:K337,"完全一致")
B26: 需确认对应的指标（近似/多个候选） | C26: =COUNTIF('指标树'!K3:K337,"近似，请核对")+COUNTIF('指标树'!K3:K337,"多个候选，请选择")
B27: 目录中未找到的指标 | C27: =COUNTIF('指标树'!K3:K337,"目录中未找到")
B28: 业务已确认的行 | C28: =COUNTA('指标树'!L3:L337)

Sheet 指标树
A1: 缩进表示上下级；点左侧“+/-”可展开、收起。〔 〕为拆解方式；↪ 为引用（该指标的完整拆解在别处，见备注） | B1: 板块 / 指标 / 拆解方式 / 比率 / 引用 | C1: 加：计入上级；减：从上级扣除；其中：属于上级但与其他项交叉，不参与加总 | D1: 来自源报表，仅用于校验 | F1: 在〔拆解方式〕行显示：该组“加/减”下级合计是否等于上级 | G1: 该板块整体情况优先看的指标 | I1: 比率类：分子 ÷ 分母 | J1: 当前问数目录中的候选，多个用“；”分隔 | L1: 请从下拉选择 | M1: 系统发现的疑点已写在这里；业务补充也写在这里 | N1: 系统导入用，与缩进一致；新增节点时请填写 | O1: 系统导入用；新增节点时请填写
A2: 指标树 | B2: 类型 | C2: 加/减/其中 | D2: 参考值 | E2: 单位 | F2: 自动校验 | G2: 核心指标 （建议） | H2: 好坏方向 （建议） | I2: 比率计算 （建议） | J2: 对应目录指标 （系统候选） | K2: 匹配情况 | L2: 业务确认 | M2: 备注 | N2: 上级指标 | O2: 拆解方式 | P2: 数值来源
A3: 一、规模与资本 | B3: 板块
A4: 总资产 | B4: 指标 | D4: 54379.99 | E4: 亿元 | G4: 是 | H4: 越大越好 | K4: 目录中未找到 | P4: 一览表 2026年7月末（全省，亿元/万户）
A5: 核心一级资本净额 | B5: 指标 | D5: 季度指标 | E5: 亿元 | H5: 越大越好 | K5: 目录中未找到 | M5: 季度指标 | P5: 一览表 2026年7月末（全省，亿元/万户）
A6: 核心一级资本充足率 | B6: 比率 | D6: 季度指标 | E6: % | H6: 越大越好 | I6: 核心一级资本净额 ÷ 风险加权资产 | K6: 目录中未找到 | M6: 季度指标 | N6: 核心一级资本净额 | O6: 比率 | P6: 一览表
A7: 一级资本净额 | B7: 指标 | D7: 季度指标 | E7: 亿元 | H7: 越大越好 | K7: 目录中未找到 | M7: 季度指标 | P7: 一览表 2026年7月末（全省，亿元/万户）
A8: 一级资本充足率 | B8: 比率 | D8: 季度指标 | E8: % | H8: 越大越好 | I8: 一级资本净额 ÷ 风险加权资产 | K8: 目录中未找到 | M8: 季度指标 | N8: 一级资本净额 | O8: 比率 | P8: 一览表
A9: 资本净额 | B9: 指标 | D9: 季度指标 | E9: 亿元 | H9: 越大越好 | K9: 目录中未找到 | M9: 季度指标 | P9: 一览表 2026年7月末（全省，亿元/万户）
A10: 资本充足率 | B10: 比率 | D10: 季度指标 | E10: % | H10: 越大越好 | I10: 资本净额 ÷ 风险加权资产 | J10: 资本充足比率 | K10: 完全一致 | M10: 季度指标 | N10: 资本净额 | O10: 比率 | P10: 一览表
A11: 风险加权资产 | B11: 指标 | D11: 季度指标 | E11: 亿元 | H11: 无明显好坏 | K11: 目录中未找到 | M11: 季度指标 | P11: 一览表 2026年7月末（全省，亿元/万户）
A12: 二、存款 | B12: 板块
A13: 各项存款 | B13: 指标 | D13: 44389.53 | E13: 亿元 | G13: 是 | H13: 越大越好 | J13: 各项存款余额 | K13: 完全一致 | P13: 一览表 2026年7月末（全省，亿元/万户）
A14: 〔按客户类型〕 | B14: 拆解方式 | F14: =IF((COUNTIFS($N$3:$N$337,N14,$O$3:$O$337,O14,$C$3:$C$337,"加")+COUNTIFS($N$3:$N$337,N14,$O$3:$O$337,O14,$C$3:$C$337,"减"))=0,"其中项，不参与加总",IF(ISNUMBER(D13)=FALSE,"上级无数值，无法校验",IF(SUMPRODUCT(($N$3:$N$337=N14)*($O$3:$O$337=O14)*(($C$3:$C$337="加")+($C$3:$C$337="减"))*(ISNUMBER($D$3:$D$337)=FALSE))>0,"部分下级无数值，无法校验",IF(ABS(D13-(SUMIFS($D$3:$D$337,$N$3:$N$337,N14,$O$3:$O$337,O14,$C$3:$C$337,"加")-SUMIFS($D$3:$D$337,$N$3:$N$337,N14,$O$3:$O$337,O14,$C$3:$C$337,"减")))<=MAX(0.05,ABS(D13)*0.0005),"✓ 合计与上级一致","✗ 合计与上级相差 "&TEXT(D13-(SUMIFS($D$3:$D$337,$N$3:$N$337,N14,$O$3:$O$337,O14,$C$3:$C$337,"加")-SUMIFS($D$3:$D$337,$N$3:$N$337,N14,$O$3:$O$337,O14,$C$3:$C$337,"减")),"#,##0.00"))))) | N14: 各项存款 | O14: 按客户类型
A15: 个人存款 | B15: 指标 | C15: 加 | D15: 33238.53 | E15: 亿元 | G15: 是 | H15: 越大越好 | J15: 个人存款余额 | K15: 完全一致 | N15: 各项存款 | O15: 按客户类型 | P15: 一览表 2026年7月末（全省，亿元/万户）
A16: 个人存款占比 | B16: 比率 | D16: 0.75 | E16: % | H16: 无明显好坏 | I16: 个人存款 ÷ 各项存款 | J16: 个人存款余额占比 | K16: 近似，请核对 | N16: 个人存款 | O16: 比率 | P16: 一览表
A17: 〔按存款类型〕 | B17: 拆解方式 | F17: =IF((COUNTIFS($N$3:$N$337,N17,$O$3:$O$337,O17,$C$3:$C$337,"加")+COUNTIFS($N$3:$N$337,N17,$O$3:$O$337,O17,$C$3:$C$337,"减"))=0,"其中项，不参与加总",IF(ISNUMBER(D15)=FALSE,"上级无数值，无法校验",IF(SUMPRODUCT(($N$3:$N$337=N17)*($O$3:$O$337=O17)*(($C$3:$C$337="加")+($C$3:$C$337="减"))*(ISNUMBER($D$3:$D$337)=FALSE))>0,"部分下级无数值，无法校验",IF(ABS(D15-(SUMIFS($D$3:$D$337,$N$3:$N$337,N17,$O$3:$O$337,O17,$C$3:$C$337,"加")-SUMIFS($D$3:$D$337,$N$3:$N$337,N17,$O$3:$O$337,O17,$C$3:$C$337,"减")))<=MAX(0.05,ABS(D15)*0.0005),"✓ 合计与上级一致","✗ 合计与上级相差 "&TEXT(D15-(SUMIFS($D$3:$D$337,$N$3:$N$337,N17,$O$3:$O$337,O17,$C$3:$C$337,"加")-SUMIFS($D$3:$D$337,$N$3:$N$337,N17,$O$3:$O$337,O17,$C$3:$C$337,"减")),"#,##0.00"))))) | N17: 个人存款 | O17: 按存款类型
A18: 个人活期存款 | B18: 指标 | C18: 加 | D18: 4647.38 | E18: 亿元 | H18: 越大越好 | J18: 个人活期存款余额 | K18: 完全一致 | N18: 个人存款 | O18: 按存款类型 | P18: 一览表 2026年7月末（全省，亿元/万户）
A19: 个人活期存款占个人存款比 | B19: 比率 | D19: 0.14 | E19: % | H19: 无明显好坏 | I19: 个人活期存款 ÷ 个人存款 | J19: 个人活期存款余额占比 | K19: 近似，请核对 | N19: 个人活期存款 | O19: 比率 | P19: 一览表
A20: 个人定期存款 | B20: 指标 | C20: 加 | D20: 28591.15 | E20: 亿元 | H20: 越大越好 | J20: 个人定期存款余额 | K20: 完全一致 | N20: 个人存款 | O20: 按存款类型 | P20: 一览表 2026年7月末（全省，亿元/万户）
A21: 个人定期存款占个人存款比 | B21: 比率 | D21: 0.86 | E21: % | H21: 无明显好坏 | I21: 个人定期存款 ÷ 个人存款 | K21: 目录中未找到 | N21: 个人定期存款 | O21: 比率 | P21: 一览表
A22: 〔按存款期限〕 | B22: 拆解方式 | F22: =IF((COUNTIFS($N$3:$N$337,N22,$O$3:$O$337,O22,$C$3:$C$337,"加")+COUNTIFS($N$3:$N$337,N22,$O$3:$O$337,O22,$C$3:$C$337,"减"))=0,"其中项，不参与加总",IF(ISNUMBER(D20)=FALSE,"上级无数值，无法校验",IF(SUMPRODUCT(($N$3:$N$337=N22)*($O$3:$O$337=O22)*(($C$3:$C$337="加")+($C$3:$C$337="减"))*(ISNUMBER($D$3:$D$337)=FALSE))>0,"部分下级无数值，无法校验",IF(ABS(D20-(SUMIFS($D$3:$D$337,$N$3:$N$337,N22,$O$3:$O$337,O22,$C$3:$C$337,"加")-SUMIFS($D$3:$D$337,$N$3:$N$337,N22,$O$3:$O$337,O22,$C$3:$C$337,"减")))<=MAX(0.05,ABS(D20)*0.0005),"✓ 合计与上级一致","✗ 合计与上级相差 "&TEXT(D20-(SUMIFS($D$3:$D$337,$N$3:$N$337,N22,$O$3:$O$337,O22,$C$3:$C$337,"加")-SUMIFS($D$3:$D$337,$N$3:$N$337,N22,$O$3:$O$337,O22,$C$3:$C$337,"减")),"#,##0.00"))))) | M22: 报表只列了四个期限，合计与个人定期存款不相等，可能还有其他期限，请业务补充或确认 | N22: 个人定期存款 | O22: 按存款期限
A23: 个人定期存款-一年期及以下 | B23: 指标 | C23: 加 | D23: 7335.94 | E23: 亿元 | H23: 越大越好 | K23: 目录中未找到 | N23: 个人定期存款 | O23: 按存款期限 | P23: 一览表 2026年7月末（全省，亿元/万户）
A24: 一年期及以下占个人定期比 | B24: 比率 | D24: 0.26 | E24: % | H24: 无明显好坏 | I24: 个人定期存款-一年期及以下 ÷ 个人定期存款 | K24: 目录中未找到 | N24: 个人定期存款-一年期及以下 | O24: 比率 | P24: 一览表
A25: 个人定期存款-二年期 | B25: 指标 | C25: 加 | D25: 3611.3 | E25: 亿元 | H25: 越大越好 | J25: 个人两年定期存款余额 | K25: 近似，请核对 | N25: 个人定期存款 | O25: 按存款期限 | P25: 一览表 2026年7月末（全省，亿元/万户）
A26: 二年期占个人定期比 | B26: 比率 | D26: 0.13 | E26: % | H26: 无明显好坏 | I26: 个人定期存款-二年期 ÷ 个人定期存款 | K26: 目录中未找到 | N26: 个人定期存款-二年期 | O26: 比率 | P26: 一览表
A27: 个人定期存款-三年期 | B27: 指标 | C27: 加 | D27: 15018.54 | E27: 亿元 | H27: 越大越好 | J27: 个人三年定期存款余额 | K27: 近似，请核对 | N27: 个人定期存款 | O27: 按存款期限 | P27: 一览表 2026年7月末（全省，亿元/万户）
A28: 三年期占个人定期比 | B28: 比率 | D28: 0.53 | E28: % | H28: 无明显好坏 | I28: 个人定期存款-三年期 ÷ 个人定期存款 | K28: 目录中未找到 | N28: 个人定期存款-三年期 | O28: 比率 | P28: 一览表
A29: 个人定期存款-五年期 | B29: 指标 | C29: 加 | D29: 473.53 | E29: 亿元 | H29: 越大越好 | K29: 目录中未找到 | N29: 个人定期存款 | O29: 按存款期限 | P29: 一览表 2026年7月末（全省，亿元/万户）
A30: 五年期占个人定期比 | B30: 比率 | D30: 0.02 | E30: % | H30: 无明显好坏 | I30: 个人定期存款-五年期 ÷ 个人定期存款 | K30: 目录中未找到 | N30: 个人定期存款-五年期 | O30: 比率 | P30: 一览表
A31: 对公存款 | B31: 指标 | C31: 加 | D31: 11151 | E31: 亿元 | G31: 是 | H31: 越大越好 | J31: 对公存款余额 | K31: 完全一致 | N31: 各项存款 | O31: 按客户类型 | P31: 一览表 2026年7月末（全省，亿元/万户）
A32: 对公存款占比 | B32: 比率 | D32: 0.25 | E32: % | H32: 无明显好坏 | I32: 对公存款 ÷ 各项存款 | J32: 对公存款余额占比 | K32: 近似，请核对 | N32: 对公存款 | O32: 比率 | P32: 一览表
A33: 〔按存款类型〕 | B33: 拆解方式 | F33: =IF((COUNTIFS($N$3:$N$337,N33,$O$3:$O$337,O33,$C$3:$C$337,"加")+COUNTIFS($N$3:$N$337,N33,$O$3:$O$337,O33,$C$3:$C$337,"减"))=0,"其中项，不参与加总",IF(ISNUMBER(D31)=FALSE,"上级无数值，无法校验",IF(SUMPRODUCT(($N$3:$N$337=N33)*($O$3:$O$337=O33)*(($C$3:$C$337="加")+($C$3:$C$337="减"))*(ISNUMBER($D$3:$D$337)=FALSE))>0,"部分下级无数值，无法校验",IF(ABS(D31-(SUMIFS($D$3:$D$337,$N$3:$N$337,N33,$O$3:$O$337,O33,$C$3:$C$337,"加")-SUMIFS($D$3:$D$337,$N$3:$N$337,N33,$O$3:$O$337,O33,$C$3:$C$337,"减")))<=MAX(0.05,ABS(D31)*0.0005),"✓ 合计与上级一致","✗ 合计与上级相差 "&TEXT(D31-(SUMIFS($D$3:$D$337,$N$3:$N$337,N33,$O$3:$O$337,O33,$C$3:$C$337,"加")-SUMIFS($D$3:$D$337,$N$3:$N$337,N33,$O$3:$O$337,O33,$C$3:$C$337,"减")),"#,##0.00"))))) | N33: 对公存款 | O33: 按存款类型
A34: 对公活期存款 | B34: 指标 | C34: 加 | D34: 3669.21 | E34: 亿元 | H34: 越大越好 | J34: 对公活期存款余额 | K34: 完全一致 | N34: 对公存款 | O34: 按存款类型 | P34: 一览表 2026年7月末（全省，亿元/万户）
A35: 对公活期存款占对公存款比 | B35: 比率 | D35: 0.33 | E35: % | H35: 无明显好坏 | I35: 对公活期存款 ÷ 对公存款 | J35: 对公活期存款余额占比 | K35: 近似，请核对 | N35: 对公活期存款 | O35: 比率 | P35: 一览表
A36: 对公定期存款 | B36: 指标 | C36: 加 | D36: 7481.79 | E36: 亿元 | H36: 越大越好 | J36: 对公定期存款余额 | K36: 完全一致 | N36: 对公存款 | O36: 按存款类型 | P36: 一览表 2026年7月末（全省，亿元/万户）
A37: 对公定期存款占对公存款比 | B37: 比率 | D37: 0.67 | E37: % | H37: 无明显好坏 | I37: 对公定期存款 ÷ 对公存款 | K37: 目录中未找到 | N37: 对公定期存款 | O37: 比率 | P37: 一览表
A38: 〔其中项〕 | B38: 拆解方式 | F38: =IF((COUNTIFS($N$3:$N$337,N38,$O$3:$O$337,O38,$C$3:$C$337,"加")+COUNTIFS($N$3:$N$337,N38,$O$3:$O$337,O38,$C$3:$C$337,"减"))=0,"其中项，不参与加总",IF(ISNUMBER(D31)=FALSE,"上级无数值，无法校验",IF(SUMPRODUCT(($N$3:$N$337=N38)*($O$3:$O$337=O38)*(($C$3:$C$337="加")+($C$3:$C$337="减"))*(ISNUMBER($D$3:$D$337)=FALSE))>0,"部分下级无数值，无法校验",IF(ABS(D31-(SUMIFS($D$3:$D$337,$N$3:$N$337,N38,$O$3:$O$337,O38,$C$3:$C$337,"加")-SUMIFS($D$3:$D$337,$N$3:$N$337,N38,$O$3:$O$337,O38,$C$3:$C$337,"减")))<=MAX(0.05,ABS(D31)*0.0005),"✓ 合计与上级一致","✗ 合计与上级相差 "&TEXT(D31-(SUMIFS($D$3:$D$337,$N$3:$N$337,N38,$O$3:$O$337,O38,$C$3:$C$337,"加")-SUMIFS($D$3:$D$337,$N$3:$N$337,N38,$O$3:$O$337,O38,$C$3:$C$337,"减")),"#,##0.00"))))) | M38: 报表以“其中”列示，与活期/定期有交叉，不参与加总 | N38: 对公存款 | O38: 其中项
A39: 保证金存款 | B39: 指标 | C39: 其中 | D39: 1774.99 | E39: 亿元 | H39: 无明显好坏 | J39: 对公保证金存款余额 | K39: 近似，请核对 | N39: 对公存款 | O39: 其中项 | P39: 一览表 2026年7月末（全省，亿元/万户）
A40: 保证金存款占对公存款比 | B40: 比率 | D40: 0.16 | E40: % | H40: 无明显好坏 | I40: 保证金存款 ÷ 对公存款 | K40: 目录中未找到 | N40: 保证金存款 | O40: 比率 | P40: 一览表
...

Sheet 选项
A1: 是 | B1: 越大越好 | C1: 加 | D1: 正确 | E1: 当日数
A2: 否 | B2: 越小越好 | C2: 减 | D2: 有误（备注说明） | E2: 进取类均值
B3: 无明显好坏 | C3: 其中 | D3: 目录中没有 | E3: 较年初
D4: 不需要 | E4: 较年初增幅
E5: 较年初增幅层级排名
E6: 较年初增幅排名
E7: 较年初增量排名
E8: 较上月
E9: 较上月增幅
E10: 较上月增幅排名
E11: 较上月增量排名
E12: 较上季
E13: 较上季增幅
E14: 较上季增幅排名
E15: 较上季增量排名
E16: 较层级均值
... E33: 全省均值
